2021-01-19 17:15:33,674 ERROR: Exception on /search [POST] [in c:\users\felipe\.virtualenvs\17_-_app_calles-c1v3uhxx\lib\site-packages\flask\app.py:1892]
Traceback (most recent call last):
  File "c:\users\felipe\.virtualenvs\17_-_app_calles-c1v3uhxx\lib\site-packages\flask\app.py", line 2447, in wsgi_app
    response = self.full_dispatch_request()
  File "c:\users\felipe\.virtualenvs\17_-_app_calles-c1v3uhxx\lib\site-packages\flask\app.py", line 1952, in full_dispatch_request
    rv = self.handle_user_exception(e)
  File "c:\users\felipe\.virtualenvs\17_-_app_calles-c1v3uhxx\lib\site-packages\flask\app.py", line 1821, in handle_user_exception
    reraise(exc_type, exc_value, tb)
  File "c:\users\felipe\.virtualenvs\17_-_app_calles-c1v3uhxx\lib\site-packages\flask\_compat.py", line 39, in reraise
    raise value
  File "c:\users\felipe\.virtualenvs\17_-_app_calles-c1v3uhxx\lib\site-packages\flask\app.py", line 1950, in full_dispatch_request
    rv = self.dispatch_request()
  File "c:\users\felipe\.virtualenvs\17_-_app_calles-c1v3uhxx\lib\site-packages\flask\app.py", line 1936, in dispatch_request
    return self.view_functions[rule.endpoint](**req.view_args)
  File "C:\Users\Felipe\Desktop\Felipe\Python\Django\workspace\17 - app_calles\app_calles\app\routes.py", line 61, in search
    wiki_link=wiki_link
  File "c:\users\felipe\.virtualenvs\17_-_app_calles-c1v3uhxx\lib\site-packages\flask\templating.py", line 140, in render_template
    ctx.app,
  File "c:\users\felipe\.virtualenvs\17_-_app_calles-c1v3uhxx\lib\site-packages\flask\templating.py", line 120, in _render
    rv = template.render(context)
  File "c:\users\felipe\.virtualenvs\17_-_app_calles-c1v3uhxx\lib\site-packages\jinja2\environment.py", line 1090, in render
    self.environment.handle_exception()
  File "c:\users\felipe\.virtualenvs\17_-_app_calles-c1v3uhxx\lib\site-packages\jinja2\environment.py", line 832, in handle_exception
    reraise(*rewrite_traceback_stack(source=source))
  File "c:\users\felipe\.virtualenvs\17_-_app_calles-c1v3uhxx\lib\site-packages\jinja2\_compat.py", line 28, in reraise
    raise value.with_traceback(tb)
  File "C:\Users\Felipe\Desktop\Felipe\Python\Django\workspace\17 - app_calles\app_calles\app\templates\info_street.html", line 1, in top-level template code
    {% extends "base.html" %}
  File "C:\Users\Felipe\Desktop\Felipe\Python\Django\workspace\17 - app_calles\app_calles\app\templates\base.html", line 28, in top-level template code
    {% block app_content %}
  File "C:\Users\Felipe\Desktop\Felipe\Python\Django\workspace\17 - app_calles\app_calles\app\templates\info_street.html", line 21, in block "app_content"
    <a href="{{ url_for('wiki_link') }}" class="text-decoration-none text-muted">
  File "c:\users\felipe\.virtualenvs\17_-_app_calles-c1v3uhxx\lib\site-packages\flask\helpers.py", line 370, in url_for
    return appctx.app.handle_url_build_error(error, endpoint, values)
  File "c:\users\felipe\.virtualenvs\17_-_app_calles-c1v3uhxx\lib\site-packages\flask\app.py", line 2216, in handle_url_build_error
    reraise(exc_type, exc_value, tb)
  File "c:\users\felipe\.virtualenvs\17_-_app_calles-c1v3uhxx\lib\site-packages\flask\_compat.py", line 39, in reraise
    raise value
  File "c:\users\felipe\.virtualenvs\17_-_app_calles-c1v3uhxx\lib\site-packages\flask\helpers.py", line 358, in url_for
    endpoint, values, method=method, force_external=external
  File "c:\users\felipe\.virtualenvs\17_-_app_calles-c1v3uhxx\lib\site-packages\werkzeug\routing.py", line 2179, in build
    raise BuildError(endpoint, values, method, self)
werkzeug.routing.BuildError: Could not build url for endpoint 'wiki_link'. Did you mean 'list' instead?
2021-01-19 17:16:44,561 INFO: App calles startup [in C:\Users\Felipe\Desktop\Felipe\Python\Django\workspace\17 - app_calles\app_calles\app\__init__.py:46]
2021-01-19 17:18:26,715 INFO: App calles startup [in C:\Users\Felipe\Desktop\Felipe\Python\Django\workspace\17 - app_calles\app_calles\app\__init__.py:46]
2021-01-19 17:20:18,576 INFO: App calles startup [in C:\Users\Felipe\Desktop\Felipe\Python\Django\workspace\17 - app_calles\app_calles\app\__init__.py:46]
2021-01-19 17:26:56,736 INFO: App calles startup [in C:\Users\Felipe\Desktop\Felipe\Python\Django\workspace\17 - app_calles\app_calles\app\__init__.py:45]
2021-01-19 19:22:48,714 INFO: App calles startup [in C:\Users\Felipe\Desktop\Felipe\Python\Django\workspace\17 - app_calles\app_calles\app\__init__.py:45]
2021-01-19 19:44:56,928 INFO: App calles startup [in C:\Users\Felipe\Desktop\Felipe\Python\Django\workspace\17 - app_calles\app_calles\app\__init__.py:45]
2021-01-20 07:52:59,336 INFO: App calles startup [in C:\Users\Felipe\Desktop\Felipe\Python\Django\workspace\17 - app_calles\app_calles\app\__init__.py:45]
2021-01-20 07:54:41,090 INFO: App calles startup [in C:\Users\Felipe\Desktop\Felipe\Python\Django\workspace\17 - app_calles\app_calles\app\__init__.py:45]
2021-01-20 08:18:30,027 INFO: App calles startup [in C:\Users\Felipe\Desktop\Felipe\Python\Django\workspace\17 - app_calles\app_calles\app\__init__.py:45]
2021-01-20 08:22:38,814 INFO: App calles startup [in C:\Users\Felipe\Desktop\Felipe\Python\Django\workspace\17 - app_calles\app_calles\app\__init__.py:45]
2021-01-20 08:22:47,122 ERROR: Exception on / [GET] [in c:\users\felipe\.virtualenvs\17_-_app_calles-c1v3uhxx\lib\site-packages\flask\app.py:1892]
Traceback (most recent call last):
  File "c:\users\felipe\.virtualenvs\17_-_app_calles-c1v3uhxx\lib\site-packages\flask\app.py", line 2447, in wsgi_app
    response = self.full_dispatch_request()
  File "c:\users\felipe\.virtualenvs\17_-_app_calles-c1v3uhxx\lib\site-packages\flask\app.py", line 1952, in full_dispatch_request
    rv = self.handle_user_exception(e)
  File "c:\users\felipe\.virtualenvs\17_-_app_calles-c1v3uhxx\lib\site-packages\flask\app.py", line 1821, in handle_user_exception
    reraise(exc_type, exc_value, tb)
  File "c:\users\felipe\.virtualenvs\17_-_app_calles-c1v3uhxx\lib\site-packages\flask\_compat.py", line 39, in reraise
    raise value
  File "c:\users\felipe\.virtualenvs\17_-_app_calles-c1v3uhxx\lib\site-packages\flask\app.py", line 1950, in full_dispatch_request
    rv = self.dispatch_request()
  File "c:\users\felipe\.virtualenvs\17_-_app_calles-c1v3uhxx\lib\site-packages\flask\app.py", line 1936, in dispatch_request
    return self.view_functions[rule.endpoint](**req.view_args)
  File "C:\Users\Felipe\Desktop\Felipe\Python\Django\workspace\17 - app_calles\app_calles\app\routes.py", line 19, in index
    api_here()
TypeError: api_here() missing 2 required positional arguments: 'latitude' and 'longitude'
2021-01-20 08:23:25,080 INFO: App calles startup [in C:\Users\Felipe\Desktop\Felipe\Python\Django\workspace\17 - app_calles\app_calles\app\__init__.py:45]
2021-01-20 08:25:42,234 INFO: App calles startup [in C:\Users\Felipe\Desktop\Felipe\Python\Django\workspace\17 - app_calles\app_calles\app\__init__.py:45]
2021-01-20 08:56:49,537 INFO: App calles startup [in C:\Users\Felipe\Desktop\Felipe\Python\Django\workspace\17 - app_calles\app_calles\app\__init__.py:45]
2021-01-20 08:57:49,558 INFO: App calles startup [in C:\Users\Felipe\Desktop\Felipe\Python\Django\workspace\17 - app_calles\app_calles\app\__init__.py:45]
2021-01-20 09:03:06,270 INFO: App calles startup [in C:\Users\Felipe\Desktop\Felipe\Python\Django\workspace\17 - app_calles\app_calles\app\__init__.py:45]
2021-01-20 09:08:23,836 INFO: App calles startup [in C:\Users\Felipe\Desktop\Felipe\Python\Django\workspace\17 - app_calles\app_calles\app\__init__.py:45]
2021-01-20 09:10:58,724 INFO: App calles startup [in C:\Users\Felipe\Desktop\Felipe\Python\Django\workspace\17 - app_calles\app_calles\app\__init__.py:45]
2021-01-20 09:12:38,436 ERROR: Exception on / [POST] [in c:\users\felipe\.virtualenvs\17_-_app_calles-c1v3uhxx\lib\site-packages\flask\app.py:1892]
Traceback (most recent call last):
  File "c:\users\felipe\.virtualenvs\17_-_app_calles-c1v3uhxx\lib\site-packages\flask\app.py", line 2447, in wsgi_app
    response = self.full_dispatch_request()
  File "c:\users\felipe\.virtualenvs\17_-_app_calles-c1v3uhxx\lib\site-packages\flask\app.py", line 1952, in full_dispatch_request
    rv = self.handle_user_exception(e)
  File "c:\users\felipe\.virtualenvs\17_-_app_calles-c1v3uhxx\lib\site-packages\flask\app.py", line 1821, in handle_user_exception
    reraise(exc_type, exc_value, tb)
  File "c:\users\felipe\.virtualenvs\17_-_app_calles-c1v3uhxx\lib\site-packages\flask\_compat.py", line 39, in reraise
    raise value
  File "c:\users\felipe\.virtualenvs\17_-_app_calles-c1v3uhxx\lib\site-packages\flask\app.py", line 1950, in full_dispatch_request
    rv = self.dispatch_request()
  File "c:\users\felipe\.virtualenvs\17_-_app_calles-c1v3uhxx\lib\site-packages\flask\app.py", line 1936, in dispatch_request
    return self.view_functions[rule.endpoint](**req.view_args)
  File "C:\Users\Felipe\Desktop\Felipe\Python\Django\workspace\17 - app_calles\app_calles\app\routes.py", line 23, in index
    context = api_here(calle_lat, calle_long)
  File "C:\Users\Felipe\Desktop\Felipe\Python\Django\workspace\17 - app_calles\app_calles\app\api_here.py", line 20, in api_here
    latitude = data['items'][0]['position']['lat']
KeyError: 'items'
